Workbook

Sheet Cover
A1: CloudSprout Inc. — Information Security Risk Assessment
A2: Risk Register Workbook | Prepared by: Alex Truong | June 2026
A3: Organization Name | B3: CloudSprout Inc.
A4: Industry | B4: B2B SaaS / E-Commerce Technology
A5: Headquarters | B5: Seattle, WA (Pioneer Square)
A6: Estimated Annual Revenue | B6: $3M – $5M ARR (estimated)
A7: Employee Count | B7: 50 employees
A8: Customer Count | B8: ~150 mid-market e-commerce brands (estimated)
A9: Regulatory Framework | B9: SOC 2 Type II (target); CCPA
A10: Assessment Framework | B10: NIST SP 800-30 Rev. 1
A11: Gap Analysis Framework | B11: NIST Cybersecurity Framework (CSF) 2.0
A12: Risk Scoring Model | B12: 5x5 Likelihood x Impact Matrix
A13: Assessment Date | B13: 46174
A14: Prepared By | B14: Alex Truong
A15: Document Status | B15: Mock Assessment – Portfolio Artifact
A17: MOCK ASSESSMENT: This workbook is a simulated professional artifact created for portfolio and professional development purposes only. CloudSprout Inc. is a fictional company. All findings, assets, personnel, and risk data are invented for educational purposes. No real organization, systems, or confidential data are referenced. This document is not affiliated with or endorsed by any real company.

Sheet Methodology
A1: TABLE 1: LIKELIHOOD SCALE
A2: Score | B2: Rating | C2: Description | D2: Frequency Proxy
A3: 1 | B3: Rare | C3: No known occurrences in this industry context. Theoretical. | D3: Once in 10+ years
A4: 2 | B4: Unlikely | C4: Has occurred in sector but not commonly. Some protective controls exist. | D4: Once in 3-10 years
A5: 3 | B5: Possible | C5: Could occur. Similar incidents documented in SaaS or startup contexts. | D5: Once in 1-3 years
A6: 4 | B6: Likely | C6: Common threat pattern. Observed frequently in comparable organizations. | D6: Once or more per year
A7: 5 | B7: Almost Certain | C7: Highly probable. Active exploits or known targeting of this environment. | D7: Multiple times per year
A10: TABLE 2: IMPACT SCALE
A11: Score | B11: Rating | C11: Financial Impact | D11: Regulatory / Reputational Consequence
A12: 1 | B12: Negligible | C12: < $10K direct cost | D12: No regulatory trigger. Unlikely to reach customers.
A13: 2 | B13: Minor | C13: $10K – $100K | D13: Possible customer notification. Low churn risk.
A14: 3 | B14: Moderate | C14: $100K – $500K | D14: Regulatory inquiry possible. Moderate churn and PR impact.
A15: 4 | B15: Major | C15: $500K – $2M | D15: Formal breach notification. Customer contract risk. Board-level.
A16: 5 | B16: Catastrophic | C16: $2M+ or business-ending | D16: Regulatory fine + litigation. Enterprise deals lost. Possible shutdown.
A19: TABLE 3: RISK LEVEL BANDS
A20: Score Range | B20: Level | C20: Required Action | D20: Notification Threshold
A21: 1 – 4 | B21: Low | C21: Monitor annually. Document in register. | D21: No immediate escalation required.
A22: 5 – 9 | B22: Medium | C22: Assign owner. Remediate within 90-180 days. | D22: Report to IT/Security Lead.
A23: 10 – 14 | B23: High | C23: Prioritize. Remediation plan within 30-90 days. | D23: Report to VP Engineering + CEO.
A24: 15 – 19 | B24: Critical | C24: Immediate action. Executive-sponsored response. | D24: CEO + Board notification.
A25: 20 – 25 | B25: Extreme | C25: Emergency response. Halt affected operations. | D25: Full board + legal counsel.

Sheet Asset Inventory
A1: Asset ID | B1: Asset Name | C1: Asset Type | D1: Criticality | E1: Data Classification | F1: Owner (Role) | G1: NIST System Category | H1: Notes
A2: A-01 | B2: CloudSprout SaaS Application | C2: Application | D2: Critical | E2: Restricted | F2: VP Engineering | G2: Major Application | H2: Core product platform hosted on AWS. Multi-tenant B2B SaaS.
A3: A-02 | B3: AWS Production Environment | C3: Infrastructure | D3: Critical | E3: Restricted | F3: VP Engineering | G3: General Support System | H3: All production workloads run in AWS us-west-2. Includes EC2, RDS, S3, Lambda.
A4: A-03 | B4: Customer Inventory & Order Data | C4: Data Store | D4: Critical | E4: Restricted | F4: VP Engineering | G4: Information Asset | H4: Core business data. Includes inventory volumes, order history, supplier contacts.
A5: A-04 | B5: API Integration Tokens (Shopify/Amazon) | C5: Data Store | D5: Critical | E5: Restricted | F5: VP Engineering | G5: Information Asset | H5: OAuth tokens and API keys enabling third-party marketplace integrations.
A6: A-05 | B6: Customer PII (Names, Emails, Addresses) | C6: Data Store | D6: High | E6: Confidential | F6: VP Customer Success | G6: Information Asset | H6: Business contact PII stored in application DB and CRM. CCPA-relevant.
A7: A-06 | B7: AWS RDS (PostgreSQL) | C7: Infrastructure | D7: Critical | E7: Restricted | F7: VP Engineering | G7: General Support System | H7: Primary relational database. Stores all application data.
A8: A-07 | B8: AWS S3 Buckets | C8: Infrastructure | D8: High | E8: Confidential | F8: VP Engineering | G8: General Support System | H8: Object storage used for file uploads, exports, and backups.
A9: A-08 | B9: Internal Admin Dashboard | C9: Application | D9: High | E9: Confidential | F9: VP Engineering | G9: Major Application | H9: Internal tooling for managing tenants, feature flags, and support access.
A10: A-09 | B10: GitHub (Source Code Repository) | C10: Third-Party Interface | D10: Critical | E10: Confidential | F10: VP Engineering | G10: Interconnected System | H10: All application source code. Includes CI/CD pipelines via GitHub Actions.
A11: A-10 | B11: Stripe Payment Integration | C11: Third-Party Interface | D11: High | E11: Confidential | F11: Finance Lead | G11: Interconnected System | H11: Payment processing outsourced to Stripe. CloudSprout holds no card data.
A12: A-11 | B12: HubSpot CRM | C12: Third-Party Interface | D12: Medium | E12: Confidential | F12: VP Sales | G12: Interconnected System | H12: Sales and customer success CRM. Contains prospect and customer contact data.
... A18: A-17 | B18: Confluence / Notion (Internal Wiki) | C18: Third-Party Interface | D18: Low | E18: Internal | F18: HR/Operations Lead | G18: Information Asset | H18: Internal knowledge base. Contains runbooks, policies, and onboarding docs.

Sheet Risk Register
A1: Risk ID | B1: Risk Title | C1: Risk Description | D1: Threat Source (NIST 800-30) | E1: Threat Event (NIST 800-30) | F1: Affected Assets | G1: Vulnerability / Predisposing Condition | H1: Likelihood (1-5) | I1: Impact (1-5) | J1: Inherent Score | K1: Inherent Level | L1: Existing Controls | M1: Control Effectiveness | N1: Residual Likelihood | O1: Residual Impact | P1: Residual Score | Q1: Residual Level | R1: Recommended Remediation | S1: Risk Owner (Role) | T1: Treatment Decision
A2: R-01 | B2: Compromised Customer API Tokens | C2: A threat actor obtains OAuth tokens or API keys used to connect customer Shopify or Amazon Seller Central accounts, enabling unauthorized access to marketplace data. | D2: Adversarial | E2: Exfiltration of credentials via application vulnerability or phishing | F2: A-02, A-04, A-09 | G2: API tokens stored in database without field-level encryption. No automatic token rotation policy. | H2: 4 | I2: 5 | J2: =H2*I2 -> 20 | K2: =IF(J2="","",IF(J2>=20,"Extreme",IF(J2>=15,"Critical",IF(J2>=10,"High",IF(J2>=5,"Medium",IF(J2>=1,"Low","")))))) -> Extreme | L2: Basic access logging in place via DataDog. AWS Secrets Manager partially used. | M2: Low | N2: 3 | O2: 4 | P2: =N2*O2 -> 12 | Q2: =IF(P2="","",IF(P2>=20,"Extreme",IF(P2>=15,"Critical",IF(P2>=10,"High",IF(P2>=5,"Medium",IF(P2>=1,"Low","")))))) -> High | R2: Implement field-level encryption for all stored tokens. Enforce token rotation every 90 days. Add anomalous API call alerting. | S2: VP Engineering | T2: Mitigate
A3: R-02 | B3: Ransomware Attack on AWS Environment | C3: Ransomware or destructive malware encrypts or corrupts production AWS resources, causing service outage and potential data loss. | D3: Adversarial | E3: Ransomware deployment via compromised credential or misconfigured service | F3: A-02, A-06, A-07 | G3: No immutable backup strategy confirmed. IAM permissions potentially over-provisioned. No tested DR runbook. | H3: 3 | I3: 5 | J3: =H3*I3 -> 15 | K3: =IF(J3="","",IF(J3>=20,"Extreme",IF(J3>=15,"Critical",IF(J3>=10,"High",IF(J3>=5,"Medium",IF(J3>=1,"Low","")))))) -> Critical | L3: AWS automated backups enabled. DataDog alerting in place. | M3: Partial | N3: 2 | O3: 4 | P3: =N3*O3 -> 8 | Q3: =IF(P3="","",IF(P3>=20,"Extreme",IF(P3>=15,"Critical",IF(P3>=10,"High",IF(P3>=5,"Medium",IF(P3>=1,"Low","")))))) -> Medium | R3: Enable S3 Object Lock for backup buckets. Implement least-privilege IAM review. Conduct annual DR tabletop exercise. | S3: VP Engineering | T3: Mitigate
A4: R-03 | B4: Misconfigured AWS S3 Bucket Exposes Customer Data | C4: An S3 bucket containing customer data or exports is inadvertently set to public, exposing sensitive business and PII data. | D4: Accidental | E4: Misconfiguration of cloud storage access controls | F4: A-02, A-03, A-07 | G4: No automated S3 policy scanning. Bucket creation not gated by IaC review. | H4: 3 | I4: 4 | J4: =H4*I4 -> 12 | K4: =IF(J4="","",IF(J4>=20,"Extreme",IF(J4>=15,"Critical",IF(J4>=10,"High",IF(J4>=5,"Medium",IF(J4>=1,"Low","")))))) -> High | L4: Some manual review during deploys. No AWS Config or Security Hub enabled. | M4: Low | N4: 2 | O4: 3 | P4: =N4*O4 -> 6 | Q4: =IF(P4="","",IF(P4>=20,"Extreme",IF(P4>=15,"Critical",IF(P4>=10,"High",IF(P4>=5,"Medium",IF(P4>=1,"Low","")))))) -> Medium | R4: Enable AWS Config with S3 public access rules. Block all public S3 access at the account level. Implement IaC (Terraform) for all bucket creation. | S4: VP Engineering | T4: Mitigate
A5: R-04 | B5: Phishing Attack Leads to Account Takeover | C5: An employee is successfully phished, resulting in credential compromise that grants an attacker access to Google Workspace, GitHub, or the AWS console. | D5: Adversarial | E5: Social engineering / spear phishing targeting employees | F5: A-09, A-12, A-14 | G5: No phishing simulation program. MFA not enforced uniformly across all systems. No security awareness training program. | H5: 4 | I5: 4 | J5: =H5*I5 -> 16 | K5: =IF(J5="","",IF(J5>=20,"Extreme",IF(J5>=15,"Critical",IF(J5>=10,"High",IF(J5>=5,"Medium",IF(J5>=1,"Low","")))))) -> Critical | L5: Google Workspace MFA available but not enforced. Some staff use hardware keys. | M5: Partial | N5: 3 | O5: 3 | P5: =N5*O5 -> 9 | Q5: =IF(P5="","",IF(P5>=20,"Extreme",IF(P5>=15,"Critical",IF(P5>=10,"High",IF(P5>=5,"Medium",IF(P5>=1,"Low","")))))) -> Medium | R5: Enforce MFA across all Google Workspace, GitHub, and AWS accounts. Deploy phishing simulation (e.g., KnowBe4). Conduct quarterly security awareness training. | S5: HR/Operations Lead | T5: Mitigate
A6: R-05 | B6: Overprivileged IAM Roles Enable Lateral Movement | C6: AWS IAM roles assigned to developers or services have excessive permissions, allowing an attacker who compromises one account to escalate privileges or access unrelated resources. | D6: Adversarial | E6: Privilege escalation via overprivileged identity | F6: A-02, A-14 | G6: IAM roles assigned broadly during startup growth. No formal IAM access review process. No separation of prod and dev environments. | H6: 3 | I6: 4 | J6: =H6*I6 -> 12 | K6: =IF(J6="","",IF(J6>=20,"Extreme",IF(J6>=15,"Critical",IF(J6>=10,"High",IF(J6>=5,"Medium",IF(J6>=1,"Low","")))))) -> High | L6: Some role-based access in place. No automated entitlement review. | M6: Low | N6: 2 | O6: 3 | P6: =N6*O6 -> 6 | Q6: =IF(P6="","",IF(P6>=20,"Extreme",IF(P6>=15,"Critical",IF(P6>=10,"High",IF(P6>=5,"Medium",IF(P6>=1,"Low","")))))) -> Medium | R6: Conduct immediate IAM access review. Implement least-privilege policy. Separate production and development AWS accounts. Automate quarterly access reviews. | S6: VP Engineering | T6: Mitigate
A7: R-06 | B7: Source Code Exfiltration via GitHub | C7: Proprietary application source code is accessed or exfiltrated due to a misconfigured repository, compromised developer credential, or accidental public repo exposure. | D7: Adversarial | E7: Unauthorized access to source code repository | F7: A-09 | G7: No mandatory branch protection policies. Developer tokens may have broad repo access. No DLP controls on GitHub. | H7: 3 | I7: 3 | J7: =H7*I7 -> 9 | K7: =IF(J7="","",IF(J7>=20,"Extreme",IF(J7>=15,"Critical",IF(J7>=10,"High",IF(J7>=5,"Medium",IF(J7>=1,"Low","")))))) -> Medium | L7: GitHub private repos used. Some team-level access controls. | M7: Partial | N7: 2 | O7: 3 | P7: =N7*O7 -> 6 | Q7: =IF(P7="","",IF(P7>=20,"Extreme",IF(P7>=15,"Critical",IF(P7>=10,"High",IF(P7>=5,"Medium",IF(P7>=1,"Low","")))))) -> Medium | R7: Enforce branch protection rules. Implement GitHub org-level secret scanning. Rotate all personal access tokens annually. Restrict repo admin rights. | S7: VP Engineering | T7: Mitigate
A8: R-07 | B8: Third-Party SaaS Breach Affects Customer Data | C8: A breach at HubSpot, Google Workspace, or another SaaS vendor exposes customer PII or business data that CloudSprout has stored in those platforms. | D8: Structural | E8: Compromise of third-party service provider | F8: A-11, A-12 | G8: No formal vendor security review process. Data minimization not enforced in CRM. No third-party risk management program. | H8: 2 | I8: 4 | J8: =H8*I8 -> 8 | K8: =IF(J8="","",IF(J8>=20,"Extreme",IF(J8>=15,"Critical",IF(J8>=10,"High",IF(J8>=5,"Medium",IF(J8>=1,"Low","")))))) -> Medium | L8: Contract terms with major vendors. Google Workspace BAA in place. | M8: Partial | N8: 2 | O8: 3 | P8: =N8*O8 -> 6 | Q8: =IF(P8="","",IF(P8>=20,"Extreme",IF(P8>=15,"Critical",IF(P8>=10,"High",IF(P8>=5,"Medium",IF(P8>=1,"Low","")))))) -> Medium | R8: Implement vendor risk questionnaire process. Review data stored in CRM and reduce to minimum necessary. Monitor vendor security advisories. | S8: HR/Operations Lead | T8: Transfer
A9: R-08 | B9: Lack of Security Awareness Training | C9: Employees take actions that inadvertently expose data or systems due to lack of formal security training, such as clicking phishing links, sharing credentials, or mishandling data. | D9: Accidental | E9: Unintentional misuse by authorized user | F9: A-12, A-13, A-17 | G9: No formal security awareness training program in place. No onboarding security checklist. | H9: 4 | I9: 3 | J9: =H9*I9 -> 12 | K9: =IF(J9="","",IF(J9>=20,"Extreme",IF(J9>=15,"Critical",IF(J9>=10,"High",IF(J9>=5,"Medium",IF(J9>=1,"Low","")))))) -> High | L9: Informal guidance from engineering team. No documented training records. | M9: Low | N9: 3 | O9: 2 | P9: =N9*O9 -> 6 | Q9: =IF(P9="","",IF(P9>=20,"Extreme",IF(P9>=15,"Critical",IF(P9>=10,"High",IF(P9>=5,"Medium",IF(P9>=1,"Low","")))))) -> Medium | R9: Implement annual security awareness training for all staff. Add security checklist to employee onboarding. Track completion. | S9: HR/Operations Lead | T9: Mitigate
A10: R-09 | B10: No Formal Incident Response Plan | C10: In the event of a security incident, the organization lacks documented procedures for detection, containment, notification, and recovery, prolonging breach impact and regulatory exposure. | D10: Structural | E10: Organizational process inadequacy | F10: A-02, A-03, A-06 | G10: No written incident response plan. No defined roles for incident response. No breach notification procedure. | H10: 2 | I10: 4 | J10: =H10*I10 -> 8 | K10: =IF(J10="","",IF(J10>=20,"Extreme",IF(J10>=15,"Critical",IF(J10>=10,"High",IF(J10>=5,"Medium",IF(J10>=1,"Low","")))))) -> Medium | L10: Informal response handled by engineering team ad hoc. | M10: Low | N10: 2 | O10: 3 | P10: =N10*O10 -> 6 | Q10: =IF(P10="","",IF(P10>=20,"Extreme",IF(P10>=15,"Critical",IF(P10>=10,"High",IF(P10>=5,"Medium",IF(P10>=1,"Low","")))))) -> Medium | R10: Draft and ratify an Incident Response Plan covering detection, containment, notification, and recovery. Assign IR roles. Conduct tabletop exercise within 90 days. | S10: CEO | T10: Mitigate
A11: R-10 | B11: Unmanaged Employee Devices (BYOD) | C11: Employee-owned devices used for work are not enrolled in MDM, may run outdated OS/software, and could be used to access company systems without adequate security controls. | D11: Accidental | E11: Device loss, theft, or malware on unmanaged endpoint | F11: A-13, A-12 | G11: No formal MDM policy. Mix of company-issued and personal devices. No screen lock or disk encryption enforcement. | H11: 3 | I11: 3 | J11: =H11*I11 -> 9 | K11: =IF(J11="","",IF(J11>=20,"Extreme",IF(J11>=15,"Critical",IF(J11>=10,"High",IF(J11>=5,"Medium",IF(J11>=1,"Low","")))))) -> Medium | L11: Some devices on Jamf MDM. No formal enrollment requirement. | M11: Partial | N11: 2 | O11: 3 | P11: =N11*O11 -> 6 | Q11: =IF(P11="","",IF(P11>=20,"Extreme",IF(P11>=15,"Critical",IF(P11>=10,"High",IF(P11>=5,"Medium",IF(P11>=1,"Low","")))))) -> Medium | R11: Mandate MDM enrollment for all devices accessing company systems. Enforce disk encryption and screen lock. Define an Acceptable Use Policy. | S11: HR/Operations Lead | T11: Mitigate
A12: R-11 | B12: No Data Retention or Deletion Policy | C12: Customer data is retained indefinitely without a defined retention schedule, creating unnecessary data exposure risk and complicating CCPA deletion requests. | D12: Structural | E12: Absence of data governance controls | F12: A-03, A-05 | G12: No data retention policy documented. No automated data deletion process. Customer offboarding may leave data in production DB. | H12: 2 | I12: 3 | J12: =H12*I12 -> 6 | K12: =IF(J12="","",IF(J12>=20,"Extreme",IF(J12>=15,"Critical",IF(J12>=10,"High",IF(J12>=5,"Medium",IF(J12>=1,"Low","")))))) -> Medium | L12: No current controls. | M12: None | N12: 2 | O12: 3 | P12: =N12*O12 -> 6 | Q12: =IF(P12="","",IF(P12>=20,"Extreme",IF(P12>=15,"Critical",IF(P12>=10,"High",IF(P12>=5,"Medium",IF(P12>=1,"Low","")))))) -> Medium | R12: Draft a Data Retention and Deletion Policy. Implement automated data purge workflows for churned customers. Map data flows for CCPA compliance. | S12: CEO / Legal | T12: Mitigate
A13: R-12 | B13: Dependency Vulnerability in Application Code | C13: Open-source libraries or third-party packages used in the CloudSprout application contain known vulnerabilities that could be exploited to compromise the platform. | D13: Adversarial | E13: Exploitation of known software vulnerability | F13: A-01, A-09 | G13: No automated dependency scanning in CI/CD pipeline. Patch cadence for dependencies informal. | H13: 3 | I13: 4 | J13: =H13*I13 -> 12 | K13: =IF(J13="","",IF(J13>=20,"Extreme",IF(J13>=15,"Critical",IF(J13>=10,"High",IF(J13>=5,"Medium",IF(J13>=1,"Low","")))))) -> High | L13: Some manual dependency review. GitHub Dependabot alerts partially configured. | M13: Partial | N13: 2 | O13: 3 | P13: =N13*O13 -> 6 | Q13: =IF(P13="","",IF(P13>=20,"Extreme",IF(P13>=15,"Critical",IF(P13>=10,"High",IF(P13>=5,"Medium",IF(P13>=1,"Low","")))))) -> Medium | R13: Enable Dependabot or Snyk in CI/CD pipeline. Establish SLA for patching critical CVEs within 14 days. Track open vulnerabilities in backlog. | S13: VP Engineering | T13: Mitigate
... A16: R-15 | B16: No Formal Access Control Policy | C16: Lack of a documented access control policy means onboarding and offboarding processes are inconsistent, potentially leaving former employees with active access to systems. | D16: Structural | E16: Inadequate access lifecycle management | F16: A-09, A-12, A-14 | G16: No written access control or offboarding procedure. Access reviews never formally conducted. | H16: 3 | I16: 3 | J16: =H16*I16 -> 9 | K16: =IF(J16="","",IF(J16>=20,"Extreme",IF(J16>=15,"Critical",IF(J16>=10,"High",IF(J16>=5,"Medium",IF(J16>=1,"Low","")))))) -> Medium | L16: HR-driven offboarding checklist exists informally. | M16: Low | N16: 2 | O16: 2 | P16: =N16*O16 -> 4 | Q16: =IF(P16="","",IF(P16>=20,"Extreme",IF(P16>=15,"Critical",IF(P16>=10,"High",IF(P16>=5,"Medium",IF(P16>=1,"Low","")))))) -> Low | R16: Document an Access Control Policy. Create a formal offboarding checklist with IT sign-off. Conduct an immediate access audit for former employees. | S16: HR/Operations Lead | T16: Mitigate
A19: RISK SUMMARY
A20: Level | B20: Inherent Count | C20: Residual Count | D20: Change
A21: Extreme | B21: =COUNTIF($K$2:$K$18,A21) -> 1 | C21: =COUNTIF($Q$2:$Q$18,A21) -> 0 | D21: =C21-B21 -> -1
A22: Critical | B22: =COUNTIF($K$2:$K$18,A22) -> 2 | C22: =COUNTIF($Q$2:$Q$18,A22) -> 0 | D22: =C22-B22 -> -2
A23: High | B23: =COUNTIF($K$2:$K$18,A23) -> 5 | C23: =COUNTIF($Q$2:$Q$18,A23) -> 1 | D23: =C23-B23 -> -4
A24: Medium | B24: =COUNTIF($K$2:$K$18,A24) -> 7 | C24: =COUNTIF($Q$2:$Q$18,A24) -> 12 | D24: =C24-B24 -> 5
A25: Low | B25: =COUNTIF($K$2:$K$18,A25) -> 0 | C25: =COUNTIF($Q$2:$Q$18,A25) -> 2 | D25: =C25-B25 -> 2

Sheet Dashboard
A1: CloudSprout Inc. — Risk Assessment Dashboard | June 2026
A3: SECTION 1: RISK DISTRIBUTION
A4: Level | B4: Inherent | C4: Residual
A5: Extreme | B5: ='Risk Register'!B21 -> 1 | C5: ='Risk Register'!C21 -> 0
A6: Critical | B6: ='Risk Register'!B22 -> 2 | C6: ='Risk Register'!C22 -> 0
A7: High | B7: ='Risk Register'!B23 -> 5 | C7: ='Risk Register'!C23 -> 1
A8: Medium | B8: ='Risk Register'!B24 -> 7 | C8: ='Risk Register'!C24 -> 12
A9: Low | B9: ='Risk Register'!B25 -> 0 | C9: ='Risk Register'!C25 -> 2
A10: Total | B10: =SUM(B5:B9) -> 15 | C10: =SUM(C5:C9) -> 15
A12: SECTION 2: TOP 5 RISKS BY RESIDUAL SCORE
A13: Risk ID | B13: Risk Title | C13: Inherent Score | D13: Inherent Level | E13: Residual Score | F13: Residual Level | G13: Primary Action
A14: R-01 | B14: Compromised Customer API Tokens | C14: 20 | D14: Extreme | E14: 12 | F14: High | G14: Encrypt API tokens; enforce rotation
A15: R-04 | B15: Phishing Attack Leads to Account Takeover | C15: 16 | D15: Critical | E15: 9 | F15: Medium | G15: Enforce MFA across all Google Workspace, GitHub, and AWS acc
A16: R-02 | B16: Ransomware Attack on AWS Environment | C16: 15 | D16: Critical | E16: 8 | F16: Medium | G16: Enable S3 Object Lock; test DR
A17: R-14 | B17: Customer Data Commingled Across Tenants | C17: 10 | D17: High | E17: 8 | F17: Medium | G17: Commission penetration test
A18: R-03 | B18: Misconfigured AWS S3 Bucket Exposes Customer Data | C18: 12 | D18: High | E18: 6 | F18: Medium | G18: Enable AWS Config with S3 public access rules. Block all public
A21: SECTION 3: KEY OBSERVATIONS
A22: 1. The risk profile is consistent with a Series A-stage SaaS company that has prioritized speed to market over formal security governance. Seven of fifteen risks carry a High or Critical inherent score.
A23: 2. The absence of a security awareness training program is the single most cross-cutting gap. It contributes to elevated likelihood scores on five separate risks.
A24: 3. AWS IAM hygiene is the most urgent technical remediation. Overprivileged roles, lack of production/dev account separation, and incomplete MFA enforcement create a layered attack surface across the cloud environment.
A25: 4. The organization holds no cardholder data (Stripe handles payments), which significantly reduces PCI-DSS exposure. The primary regulatory risk is CCPA due to stored customer PII and the absence of a data retention policy.
A26: 5. Multi-tenant data isolation (R-14) is the highest-impact residual risk at a score of 8. A single tenant isolation failure would be catastrophic to enterprise sales pipeline and SOC 2 readiness.
A27: 6. No penetration test has ever been conducted. For an organization targeting enterprise customers and SOC 2 certification, annual pen testing is an expected baseline control.
A28: 7. With focused effort across IAM, MFA enforcement, and security training, the organization can reduce the average residual risk score by an estimated 25-30% within one year. This is a realistic and achievable improvement horizon.
A30: SECTION 4: PRIORITY ACTION TIMELINE
A31: Horizon | B31: Action | C31: Related Risk(s)
A32: 0 – 30 Days | B32: Enforce MFA across all AWS, GitHub, and Google Workspace accounts | C32: R-04, R-05
A33: 0 – 30 Days | B33: Conduct IAM access review; remove overprivileged roles | C33: R-05
A34: 0 – 30 Days | B34: Block all public S3 access at AWS account level | C34: R-03
A35: 0 – 30 Days | B35: Enable AWS CloudTrail in all regions | C35: R-13
A36: 30 – 90 Days | B36: Draft and ratify Incident Response Plan; assign IR roles | C36: R-09
A37: 30 – 90 Days | B37: Enable Dependabot or Snyk in CI/CD pipeline | C37: R-12
A38: 30 – 90 Days | B38: Implement field-level encryption for stored API tokens | C38: R-01
A39: 30 – 90 Days | B39: Commission web application penetration test | C39: R-14
A40: 90 – 180 Days | B40: Deploy security awareness training for all staff | C40: R-08
A41: 90 – 180 Days | B41: Draft Data Retention and Deletion Policy | C41: R-11
A42: 90 – 180 Days | B42: Implement MDM enrollment requirement for all devices | C42: R-10
... A47: Ongoing | B47: Monitor vendor security advisories for SaaS tools | C47: R-07

Sheet NIST CSF Gap Analysis
A1: CSF Function | B1: Category ID | C1: Category Description | D1: Assumed Current State | E1: Maturity (1-5) | F1: Gap Description | G1: Related Risk IDs
A2: FUNCTION: GOVERN
A3: GOVERN | B3: GV.OC-01 | C3: Organizational mission and business context inform cybersecurity objectives | D3: Security has not been formally connected to business strategy. Leadership is aware of risk but no documented security objectives exist. | E3: 1 | F3: No written information security policy or cybersecurity strategy. | G3: All
A4: GOVERN | B4: GV.OC-02 | C4: Internal and external stakeholder expectations are understood and considered | D4: Customer contract requirements are known to sales but not formally captured in a risk or compliance context. | E4: 1 | F4: No formal process for capturing stakeholder security requirements. | G4: R-07
A5: GOVERN | B5: GV.RM-01 | C5: Risk management strategy is established, communicated, and reviewed | D5: No formal risk management strategy exists. Risk decisions are made ad hoc by the VP of Engineering. | E5: 1 | F5: No documented risk appetite statement or risk management policy. | G5: All
A6: GOVERN | B6: GV.RM-02 | C6: Risk tolerance is determined, communicated, and reviewed | D6: Implicit risk tolerance only. No board or executive-level risk appetite statement exists. | E6: 1 | F6: No risk acceptance criteria. Treatment decisions made informally with no documentation. | G6: R-01, R-14
A7: GOVERN | B7: GV.SC-01 | C7: Cybersecurity supply chain risk management is integrated into organization-wide risk management | D7: No vendor security review process. SaaS tools adopted without security evaluation. | E7: 1 | F7: No vendor risk management program or security questionnaire process. | G7: R-07
A8: GOVERN | B8: GV.SC-02 | C8: Cybersecurity roles and responsibilities for suppliers and customers are established | D8: Third-party integrations are known but not formally inventoried from a risk perspective. | E8: 2 | F8: No formal third-party inventory. No periodic vendor security review cycle. | G8: R-07
A9: GOVERN | B9: GV.PO-01 | C9: Policy for managing cybersecurity risks is established, communicated, and enforced | D9: No formal information security policy of any kind exists. | E9: 1 | F9: No written security policy, acceptable use policy, or access control policy. | G9: R-08, R-15
A10: GOVERN | B10: GV.PO-02 | C10: Cybersecurity roles and responsibilities are established and communicated | D10: Engineering team manages security informally. No CISO or dedicated security role exists. | E10: 2 | F10: No formal security role assignments. Responsibility diffused across VP Engineering. | G10: R-09
A11: FUNCTION: IDENTIFY
A12: IDENTIFY | B12: ID.AM-01 | C12: Assets that enable the organization to achieve business purposes are identified and managed | D12: Laptop inventory maintained informally by HR. No formal hardware CMDB or asset management tool. | E12: 2 | F12: No formal asset management system integrated with security processes. | G12: R-10, R-13
A13: IDENTIFY | B13: ID.AM-02 | C13: Inventories of software, services, and systems are maintained | D13: Developers know the technology stack but no formal software inventory exists. | E13: 2 | F13: No CMDB or software asset management tool. Inventory exists only in engineer memory. | G13: R-12
A14: IDENTIFY | B14: ID.AM-03 | C14: Representations of the organization's authorized network communication and data flows are maintained | D14: Data flows are understood by engineering but not formally documented. | E14: 1 | F14: No data flow diagram. PII and API token flows not mapped across systems. | G14: R-01, R-11
A15: IDENTIFY | B15: ID.AM-05 | C15: Assets are prioritized based on classification, criticality, resources, and impact on the mission | D15: No formal data classification scheme applied to assets prior to this assessment. | E15: 1 | F15: No data classification policy. Restricted and Confidential data handled without distinction. | G15: R-03, R-05
A16: IDENTIFY | B16: ID.RA-01 | C16: Vulnerabilities in assets are identified, validated, and recorded | D16: GitHub Dependabot partially enabled. No AWS Config, Security Hub, or vulnerability scanner. | E16: 2 | F16: Vulnerability identification is incomplete and not systematic across all assets. | G16: R-12, R-13
A17: IDENTIFY | B17: ID.RA-02 | C17: Cyber threat intelligence is received from information sharing forums and sources | D17: No formal threat intelligence program. Informal awareness from engineering team only. | E17: 1 | F17: No subscription to threat feeds. No structured threat analysis process. | G17: R-01, R-04
A18: IDENTIFY | B18: ID.RA-03 | C18: Internal and external threats to the organization are identified and recorded | D18: Threats identified as part of this assessment only. No recurring identification process. | E18: 1 | F18: No formal threat identification process prior to this engagement. | G18: All
A19: IDENTIFY | B19: ID.RA-06 | C19: Risks to the organization's objectives are prioritized and communicated | D19: No risk register or prioritization process existed prior to this assessment. | E19: 1 | F19: No documented risk treatment decisions. No risk register maintained. | G19: All
A20: IDENTIFY | B20: ID.IM-01 | C20: Improvements are identified from security assessments | D20: No formal security evaluation or improvement cycle in place. | E20: 1 | F20: No security review cadence. No post-incident lessons learned process. | G20: R-09
A21: FUNCTION: PROTECT
A22: PROTECT | B22: PR.AA-01 | C22: Identities and credentials for authorized users, services, and hardware are managed | D22: Google Workspace and GitHub accounts exist. MFA available but not enforced uniformly. | E22: 2 | F22: No uniform MFA enforcement. No privileged access management program. | G22: R-04, R-05
A23: PROTECT | B23: PR.AA-02 | C23: Identities are proofed and bound to credentials based on the context of interactions | D23: Authentication in place for all major systems. MFA gap remains on several accounts. | E23: 2 | F23: Incomplete MFA coverage. No hardware token requirement for privileged access. | G23: R-04
A24: PROTECT | B24: PR.AA-03 | C24: Users, services, and hardware are authenticated | D24: Standard password plus optional MFA across most systems. | E24: 2 | F24: MFA not enforced. Some accounts rely on password only. | G24: R-04
A25: PROTECT | B25: PR.AA-05 | C25: Access permissions, entitlements, and authorizations are defined in a policy, managed, enforced, and reviewed | D25: No formal access review process. No offboarding verification step in HR process. | E25: 1 | F25: No access recertification cycle. Former employee accounts may remain active. | G25: R-15
A26: PROTECT | B26: PR.DS-01 | C26: The confidentiality, integrity, and availability of data-at-rest are protected | D26: AWS encryption-at-rest enabled for RDS and S3. API tokens not field-level encrypted. | E26: 3 | F26: Field-level encryption for stored API tokens is missing. Partial control only. | G26: R-01
A27: PROTECT | B27: PR.DS-02 | C27: The confidentiality, integrity, and availability of data-in-transit are protected | D27: TLS enforced across all application endpoints. | E27: 4 | F27: Minor gap: internal service-to-service communication not fully verified. | G27: None
A28: PROTECT | B28: PR.DS-10 | C28: Data is managed through its life cycle | D28: No data retention or deletion policy. No automated purge workflows. | E28: 1 | F28: Customer data retained indefinitely. No process for honoring CCPA deletion requests. | G28: R-11
A29: PROTECT | B29: PR.PS-01 | C29: Configuration management practices are established and applied | D29: Infrastructure deployed via mix of manual console actions and partial IaC. No formal baseline. | E29: 2 | F29: No configuration management baseline. S3 policies not enforced through IaC. | G29: R-03
A30: PROTECT | B30: PR.PS-02 | C30: Software is maintained, replaced, and removed commensurate with risk | D30: OS and dependency patching informal. No SLA for critical CVE remediation. | E30: 2 | F30: No formal patch management policy. Dependabot alerts not consistently actioned. | G30: R-12
A31: PROTECT | B31: PR.IR-01 | C31: Response to incidents is managed | D31: No written incident response plan exists. | E31: 1 | F31: No documented IR plan. No defined roles, procedures, or notification thresholds. | G31: R-09
A32: PROTECT | B32: PR.AT-01 | C32: Personnel are provided with awareness and training so that they possess the knowledge and skills to perform general tasks with cybersecurity risks in mind | D32: No formal security awareness training program in place. | E32: 1 | F32: No security awareness training. No phishing simulation program. | G32: R-08
A33: FUNCTION: DETECT
A34: DETECT | B34: DE.AE-02 | C34: Potentially adverse events are analyzed to better characterize them | D34: DataDog monitors application performance. No security-specific alerting rules defined. | E34: 2 | F34: Monitoring is performance-focused, not security-focused. No anomaly detection for access patterns. | G34: R-13
A35: DETECT | B35: DE.AE-03 | C35: Information is correlated from multiple sources | D35: Logs exist in DataDog and CloudWatch but are not centrally correlated. | E35: 2 | F35: No SIEM or log correlation. Multi-source security analysis is not possible in current setup. | G35: R-13
A36: DETECT | B36: DE.AE-06 | C36: Information on adverse events is provided to authorized staff and tools | D36: No defined process for alerting security or executive stakeholders of events. | E36: 1 | F36: No alert routing to security-accountable roles. Events surface only if engineering notices. | G36: R-09, R-13
A37: DETECT | B37: DE.CM-01 | C37: Networks and network services are monitored to find potentially adverse events | D37: CloudWatch metrics exist. No VPC flow logs enabled. | E37: 2 | F37: VPC flow logs not enabled. Network-level monitoring is incomplete. | G37: R-02, R-13
A38: DETECT | B38: DE.CM-03 | C38: Personnel activity and technology usage are monitored to find potentially adverse events | D38: No user behavior monitoring. No DLP controls in place. | E38: 1 | F38: No monitoring of data access patterns or anomalous user behavior across systems. | G38: R-01, R-06
A39: DETECT | B39: DE.CM-09 | C39: Computing hardware and software, runtime environments, and their data are monitored to find potentially adverse events | D39: No automated vulnerability scanning of the production environment. | E39: 1 | F39: No DAST or infrastructure scanning. Dependabot only partially configured. | G39: R-12, R-14
A40: FUNCTION: RESPOND
...

Sheet Risk Justification Log
A1: Risk ID
A2: R-01 | B2: Compromised Customer API Tokens | C2: Rated 4 (Likely). Credential theft and API key exfiltration are among the most commonly reported attack vectors in SaaS environments per CISA advisories. OAuth token abuse is specifically documented in cloud-native supply chain incidents. | D2: Rated 5 (Catastrophic). Compromised marketplace tokens give attackers direct access to customer Shopify and Amazon accounts, creating liability that extends beyond CloudSprout to third-party platforms. Contract loss risk is very high. | E2: Existing controls rated Low effectiveness. DataDog logging captures volume but not semantic anomalies. Partial Secrets Manager use means tokens may still reside in environment variables or config files. | F2: Residual score 12 (High). Encryption and rotation policy would reduce likelihood to 3, and detection controls would reduce impact to 4, yielding 12. Score reflects that token security is a multi-step program, not a single fix. | G2: NIST CSF PR.DS-1, PR.DS-2; NIST SP 800-30 Table D-2
A3: R-02 | B3: Ransomware Attack on AWS Environment | C3: Rated 3 (Possible). Ransomware targeting cloud-native startups is documented but less frequent than targeting on-premise environments. Verizon DBIR 2023 shows ransomware in approximately 24% of breaches across all sectors. A startup's AWS footprint is lower-profile than enterprise targets. | D3: Rated 5 (Catastrophic). Total or partial encryption of the production AWS environment would cause complete service outage, potential data loss, and likely breach of customer SLAs. For a 50-person SaaS company, a multi-day outage could be business-ending. | E3: Partial effectiveness. AWS automated snapshots provide some recovery capability but immutable backups have not been confirmed. No tested DR runbook means recovery time is unknown and likely extended. | F3: Residual score 8 (Medium). Immutable backups, least-privilege IAM, and a tested DR plan would reduce impact confidence to 4 and likelihood to 2, yielding 8. Controls must be proven, not just in place. | G3: NIST CSF RC.RP-1, PR.IP-4; NIST SP 800-30 Table E-2
A4: R-03 | B4: Misconfigured S3 Bucket | C4: Rated 3 (Possible). S3 misconfiguration is one of the most frequently reported cloud exposure types. AWS itself has issued guidance multiple times. Organizations without IaC or Config enforcement routinely create exposed buckets. | D4: Rated 4 (Major). Public exposure of customer data would trigger CCPA notification obligations, damage enterprise sales conversations, and potentially violate customer data processing agreements. | E4: Low effectiveness. Manual deploy review is insufficient at development velocity. No automated scanning means a misconfiguration could persist for weeks. | F4: Residual score 6 (Medium). AWS account-level S3 block settings reduce likelihood to near-certain prevention for public exposure, bringing likelihood to 2 and impact to 3, yielding 6. | G4: NIST CSF PR.AC-3, PR.DS-5; NIST SP 800-30 Table D-3
A5: R-04 | B5: Phishing Attack / Account Takeover | C5: Rated 4 (Likely). Phishing is the number one initial access vector per FBI IC3 2023 data. Organizations without phishing simulation programs show significantly higher susceptibility rates. 50 employees in a hybrid work model with no formal training is a high-risk profile. | D5: Rated 4 (Major). Account takeover of a developer or admin credential grants access to GitHub, AWS, or Google Workspace. Blast radius is wide. A Google Workspace compromise alone would expose all company email and shared files. | E5: Partial effectiveness. MFA availability does not equal MFA enforcement. Partial enforcement is functionally equivalent to no enforcement for the uncovered accounts. | F5: Residual score 9 (Medium). Enforced MFA reduces likelihood from 4 to 3. Training and simulation reduce impact confidence to 3. Score of 9 reflects that phishing will remain a persistent threat even with controls. | G5: NIST CSF PR.AC-1, PR.AT-1; NIST SP 800-30 Table D-1
A6: R-05 | B6: Overprivileged IAM Roles | C6: Rated 3 (Possible). Overprivileged IAM is a near-universal finding in startup environments. The pressure to ship quickly leads to broad role assignments that are rarely revisited. AWS's own Well-Architected reviews frequently cite this finding. | D6: Rated 4 (Major). IAM privilege escalation in AWS can grant access to production databases, S3 buckets, and secret stores. A single compromised developer credential with broad permissions is equivalent to a root-level access event. | E6: Low effectiveness. Role-based access exists at a surface level but was not formally reviewed. No evidence of access certification or quarterly review process. | F6: Residual score 6 (Medium). Least-privilege enforcement with separated prod/dev accounts reduces likelihood to 2 and impact to 3, yielding 6. | G6: NIST CSF PR.AC-4, PR.AC-6; NIST SP 800-53 AC-6
A7: R-06 | B7: Source Code Exfiltration via GitHub | C7: Rated 3 (Possible). Supply chain and source code attacks are increasing per CISA advisories, particularly against developer tooling. GitHub credential abuse is among the top reported vectors. | D7: Rated 3 (Moderate). Exposure of proprietary source code damages competitive position and may reveal security vulnerabilities. Financial impact is moderate unless code contains embedded secrets. | E7: Partial effectiveness. Private repos reduce surface area but do not prevent insider or compromised-credential access. | F7: Residual score 6 (Medium). Branch protection and secret scanning bring likelihood to 2 and impact to 3. | G7: NIST CSF PR.DS-6, PR.AC-3; NIST SP 800-30 Table D-2
A8: R-07 | B8: Third-Party SaaS Breach | C8: Rated 2 (Unlikely). Major SaaS breaches (Google, HubSpot) are rare. However, HubSpot did experience a notable data incident in 2022, and vendor risk is a real vector for downstream exposure. | D8: Rated 4 (Major). A breach at a CRM or collaboration platform holding customer PII creates breach notification obligations and damages customer trust. | E8: Partial effectiveness. Contract terms provide some recourse but do not prevent data exposure. Google Workspace BAA addresses some HIPAA-adjacent requirements. | F8: Residual score 6 (Medium). Data minimization and vendor monitoring reduce the organization's exposure surface. | G8: NIST CSF ID.SC-2, ID.SC-4; NIST SP 800-30 Table D-5
A9: R-08 | B9: Lack of Security Awareness Training | C9: Rated 4 (Likely). Without a training program, phishing susceptibility rates in comparable organizations typically exceed 25% per KnowBe4 benchmarking data. This is not speculative; it is a measured outcome. | D9: Rated 3 (Moderate). Training deficits amplify likelihood across many risk categories but the direct impact of a training failure is typically moderate unless it enables a higher-severity event. | E9: Low effectiveness. Informal guidance from engineering is insufficient against targeted social engineering. | F9: Residual score 6 (Medium). A training program reduces susceptibility but cannot eliminate it. | G9: NIST CSF PR.AT-1, PR.AT-2; NIST SP 800-30 Table D-1
A10: R-09 | B10: No Incident Response Plan | C10: Rated 2 (Unlikely as a standalone trigger). The risk is not that the absence of a plan causes an incident, but that when an incident occurs, the lack of a plan extends damage duration and exposure. | D10: Rated 4 (Major). Without defined roles and procedures, containment time increases. For a data breach, every additional hour of containment delay increases regulatory exposure under CCPA's 72-hour notification window. | E10: Low effectiveness. Ad hoc response may work for minor issues but is inadequate for structured incidents requiring legal coordination. | F10: Residual score 6 (Medium). A documented and exercised plan reduces average response time and limits regulatory exposure. | G10: NIST CSF RS.RP-1, RS.CO-2; NIST SP 800-61 Rev. 2
A11: R-10 | B11: Unmanaged Employee Devices | C11: Rated 3 (Possible). Unmanaged endpoint incidents are common in distributed work models. Device theft or personal malware is a realistic threat for a hybrid 50-person team. | D11: Rated 3 (Moderate). A compromised device provides a credential or session token that can be used to access cloud systems. Impact is bounded by what the individual employee can access. | E11: Partial effectiveness. Some MDM coverage exists but is not universal. | F11: Residual score 6 (Medium). Full MDM enrollment with disk encryption reduces likelihood to 2 and impact to 3. | G11: NIST CSF PR.AC-3, PR.DS-1; CIS Control 4
A12: R-11 | B12: No Data Retention Policy | C12: Rated 2 (Unlikely to cause direct incident). The risk manifests as regulatory non-compliance rather than an immediate security event. | D12: Rated 3 (Moderate). CCPA requires honoring deletion requests within 45 days. Inability to purge data creates ongoing compliance exposure and litigation risk. | E12: No controls in place. | F12: Residual score 6 (Medium). A documented policy with automated purge workflows addresses the regulatory exposure. | G12: NIST CSF ID.AM-5, PR.DS-3; CCPA Section 1798.105
A13: R-12 | B13: Dependency Vulnerabilities | C13: Rated 3 (Possible). CVE databases report thousands of package vulnerabilities monthly. Without automated scanning, critical vulnerabilities in dependencies are discovered late or not at all. | D13: Rated 4 (Major). Exploited dependency vulnerabilities (e.g., Log4Shell-style events) can provide remote code execution in production environments. Impact in a multi-tenant SaaS environment is amplified. | E13: Partial effectiveness. Dependabot partially configured is better than nothing but inconsistent. | F13: Residual score 6 (Medium). Automated scanning with enforced SLA for critical CVEs reduces likelihood to 2 and maintains impact at 3. | G13: NIST CSF PR.IP-12, ID.RA-1; NIST SP 800-53 SI-2
... A16: R-15 | B16: No Formal Access Control Policy | C16: Rated 3 (Possible). Without a formal offboarding checklist, former employee accounts are commonly found active in post-incident reviews. Employee turnover at a 50-person startup is a real and recurring trigger. | D16: Rated 3 (Moderate). A former employee with active access could exfiltrate data or cause disruption. Impact is bounded by that individual's access scope. | E16: Low effectiveness. Informal HR checklist has no IT verification step. | F16: Residual score 4 (Low). A documented policy with IT sign-off brings residual likelihood to 2 and impact to 2. | G16: NIST CSF PR.AC-1, PR.AC-3; NIST SP 800-53 AC-2
